Workbook

Sheet Cover page
G13: SEPARATION PROCESSES (SETK 3323)
G15: SEMESTER 1 SESSION 2025/2026
F17: CORNERSTONE PROJECT
D19: TOPIC: AMINATION OF 100,000 MTA OF ETHYLENE OXIDE FOR MONOETHANOLAMINE PRODUCTION
F21: LECTURER: DR. SHUHADA ATIKA BINTI IDRUS SAIDI
G23: SECTION 1 - GROUP 2
F25: GROUP MEMBERS | I25: MATRIC NUMBER
F26: CHANG QING YIU | I26: A23KT0049
F27: CHEONG WEI XIN | I27: A23KT0051
F28: E SHAO YUAN | I28: A23KT0064
F29: YONG ZHENG ZHAO | I29: A23KT0254

Sheet Answer Table
A1: Table 1: Summary of Mass Balance and Energy Balance Table (with answers)
A2: Stream No. | B2: 1 | C2: 2 | D2: 3 | E2: 4 | F2: 5 | G2: 6 | H2: 7 | I2: 8 | J2: 9 | K2: 10 | L2: 11 | M2: 12 | N2: 13 | O2: 14 | P2: 15 | Q2: 16 | R2: 17 | S2: 18 | T2: 19 | U2: 20 | V2: 21 | X2: Components | Y2: Molecular Weight (kg/kmol)
A3: Stream | B3: Fresh Feed AM | C3: Fresh Feed EO | D3: Heater Feed AM | E3: Heater Feed EO | F3: Mixed Recycle and Fresh Feed EO | G3: Reactor Output | H3: Cooler 1 Output | I3: PS Top | J3: PS Bottom | K3: Heater 3 Output | L3: DC 1 Distillate | M3: DC 1 Bottom | N3: DC 2 Distillate | O3: DC 2 Bottom | P3: Cooler 2 Outlet | Q3: Solvent Feed | R3: Extract | S3: Raffinate | T3: DC 3 Distillate | U3: DC 3 Bottom | V3: Heated Recycle EO | X3: NH₃ (AM) | Y3: =17.031 -> 17.031
A4: From | B4: Storage Tank AM | C4: Storage Tank EO | D4: Heater 1 | E4: Heater 2 | F4: Holding Tank | G4: Reactor | H4: Cooler 1 | I4: Phase Separator | K4: Heater 3 | L4: Distillation Column 1 | N4: Distillation Column 2 | P4: Cooler 2 | Q4: Storage Tank Solvent | R4: Liquid-Liquid Extractor | T4: Distillation Column 3 | V4: Heater 4 | X4: C₂H₄O (EO) | Y4: 44.053
A5: To | B5: Heater 1 | C5: Heater 2 | D5: Reactor | E5: Holding Tank | F5: Reactor | G5: Cooler 1 | H5: Phase Separator | I5: Heater 3 | J5: Distillation Column 1 | K5: Ammonia Collection Tank | L5: Cooler 2 | M5: Distillation Column 2 | N5: By Product 1 Tank | O5: By Product 2 Tank | P5: Liquid-Liquid Extractor | Q5: Liquid-Liquid Extractor | R5: Heater 4 | S5: Distillation Column 3 | T5: Main Product Tank | U5: Solvent Collection Tank | V5: Holding Tank | X5: C₂H₇NO (MEA) | Y5: 61.083
A6: Vapour Fraction | B6: ='Heater 1'!J19 -> 1 | C6: ='Heater 2'!I27 -> 1 | D6: =Reactor!D27 -> 1 | E6: ='Holding Tank'!E23 -> 1 | F6: =Reactor!F56 -> 1 | G6: ='Cooler 1'!E20 -> 1 | H6: ='Phase Separator'!E35 -> 0.51798561 | I6: ='Heater 3'!E18 -> 1 | J6: ='Distillation Column 1 '!G29 -> 0 | K6: ='Heater 3'!O18 -> 0 | L6: ='Cooler 2'!E19 -> 1 | M6: ='Distillation Column 2'!E20 -> 0 | N6: ='Distillation Column 2'!H50 -> 0 | O6: ='Distillation Column 2'!N20 -> 0 | P6: ='Liquid-liquid Extractor '!E32 -> 0 | Q6: ='Liquid-liquid Extractor '!M29 -> 0 | R6: ='Heater 4'!J20 -> 0 | S6: ='Distillation Column 3'!E33 -> 0 | T6: ='Distillation Column 3'!H65 -> 0 | U6: ='Distillation Column 3'!L25 -> 0 | V6: ='Holding Tank'!H53 -> 1 | X6: C₄H₁₁NO₂ (DEA) | Y6: 105.136
A7: Total Mass Flowrate (kg/hr) | B7: ='Heater 1'!J3 -> 7322.0171 | C7: ='Heater 2'!I11 -> 9687.5 | D7: =Reactor!D11 -> 7322.0171 | E7: ='Holding Tank'!E7 -> 9687.5 | F7: =Reactor!F40 -> 12626.263 | G7: ='Cooler 1'!E4 -> 19948.09 | H7: ='Phase Separator'!E19 -> 19948.09 | I7: ='Heater 3'!E2 -> 4393.2102 | J7: ='Distillation Column 1 '!G13 -> 15554.88 | K7: ='Heater 3'!O2 -> 4393.2102 | L7: ='Cooler 2'!E3 -> 11588.625 | M7: ='Distillation Column 2'!E4 -> 3966.2549 | N7: ='Distillation Column 2'!H34 -> 1661.7623 | O7: ='Distillation Column 2'!N4 -> 2304.4927 | P7: ='Liquid-liquid Extractor '!E16 -> 11588.625 | Q7: ='Liquid-liquid Extractor '!M13 -> 19423.574 | R7: ='Heater 4'!J4 -> 2938.7626 | S7: ='Distillation Column 3'!E17 -> 28073.436 | T7: ='Distillation Column 3'!H49 -> 8552.776 | U7: ='Distillation Column 3'!L9 -> 19520.66 | V7: ='Holding Tank'!H37 -> 2938.7626 | X7: C₆H₁₅NO₃ (TEA) | Y7: 149.188
A8: Total Molar Flowrate (kmol/hr) | B8: ='Heater 1'!J4 -> 429.92291 | C8: ='Heater 2'!I12 -> 219.90557 | D8: =Reactor!D12 -> 429.92291 | E8: ='Holding Tank'!E8 -> 219.90557 | F8: =Reactor!F41 -> 286.61527 | G8: ='Cooler 1'!E5 -> 497.99404 | H8: ='Phase Separator'!E20 -> 497.99404 | I8: ='Heater 3'!E3 -> 257.95375 | J8: ='Distillation Column 1 '!G14 -> 240.04029 | K8: ='Heater 3'!O3 -> 257.95375 | L8: ='Cooler 2'!E4 -> 208.62009 | M8: ='Distillation Column 2'!E5 -> 31.420199 | N8: ='Distillation Column 2'!H35 -> 15.879037 | O8: ='Distillation Column 2'!N5 -> 15.541162 | P8: ='Liquid-liquid Extractor '!E17 -> 208.62009 | Q8: ='Liquid-liquid Extractor '!M14 -> 312.93014 | R8: ='Heater 4'!J5 -> 66.709705 | S8: ='Distillation Column 3'!E18 -> 454.84052 | T8: ='Distillation Column 3'!H50 -> 140.39849 | U8: ='Distillation Column 3'!L10 -> 314.44203 | V8: ='Holding Tank'!H38 -> 66.709705 | X8: C₂H₆O₂ (EG) | Y8: 62.07
A9: Components Molar Flowrate (kmol/hr)
A10: AM | B10: ='Heater 1'!J6 -> 429.92291 | D10: =Reactor!D14 -> 429.92291 | G10: ='Cooler 1'!E7 -> 257.95375 | H10: ='Phase Separator'!E22 -> 257.95375 | I10: ='Heater 3'!E5 -> 257.95375 | K10: ='Heater 3'!O5 -> 257.95375
A11: EO | C11: ='Heater 2'!I15 -> 219.90557 | E11: ='Holding Tank'!E11 -> 219.90557 | F11: =Reactor!F44 -> 286.61527 | G11: ='Cooler 1'!E8 -> 68.071127 | H11: ='Phase Separator'!E23 -> 68.071127 | J11: ='Distillation Column 1 '!G17 -> 68.071127 | L11: ='Cooler 2'!E7 -> 68.071127 | P11: ='Liquid-liquid Extractor '!E20 -> 68.071127 | R11: ='Heater 4'!J8 -> 66.709705 | S11: ='Distillation Column 3'!E21 -> 1.3614225 | T11: ='Distillation Column 3'!H53 -> 1.3614225 | V11: ='Holding Tank'!H41 -> 66.709705
A12: MEA | G12: ='Cooler 1'!E9 -> 143.30764 | H12: ='Phase Separator'!E24 -> 143.30764 | J12: ='Distillation Column 1 '!G18 -> 143.30764 | L12: ='Cooler 2'!E8 -> 140.44148 | M12: ='Distillation Column 2'!E9 -> 2.8661527 | N12: ='Distillation Column 2'!H39 -> 2.8661527 | P12: ='Liquid-liquid Extractor '!E21 -> 140.44148 | S12: ='Distillation Column 3'!E22 -> 140.44148 | T12: ='Distillation Column 3'!H54 -> 139.03707 | U12: ='Distillation Column 3'!L14 -> 1.4044148
A13: DEA | G13: ='Cooler 1'!E10 -> 10.748073 | H13: ='Phase Separator'!E25 -> 10.748073 | J13: ='Distillation Column 1 '!G19 -> 10.748073 | L13: ='Cooler 2'!E9 -> 0.10748073 | M13: ='Distillation Column 2'!E10 -> 10.640592 | N13: ='Distillation Column 2'!H40 -> 10.321374 | O13: ='Distillation Column 2'!N10 -> 0.31921776 | P13: ='Liquid-liquid Extractor '!E22 -> 0.10748073 | S13: ='Distillation Column 3'!E23 -> 0.10748073 | U13: ='Distillation Column 3'!L15 -> 0.10748073
A14: TEA | G14: ='Cooler 1'!E11 -> 17.913455 | H14: ='Phase Separator'!E26 -> 17.913455 | J14: ='Distillation Column 1 '!G20 -> 17.913455 | M14: ='Distillation Column 2'!E11 -> 17.913455 | N14: ='Distillation Column 2'!H41 -> 2.6915103 | O14: ='Distillation Column 2'!N11 -> 15.221944
A15: EG | Q15: ='Liquid-liquid Extractor '!M21 -> 312.93014 | S15: ='Distillation Column 3'!E25 -> 312.93014 | U15: ='Distillation Column 3'!L17 -> 312.93014
A16: Molar Compositions
A17: AM | B17: ='Heater 1'!J13 -> 1 | D17: =Reactor!D21 -> 1 | G17: ='Cooler 1'!E14 -> 0.51798561 | H17: ='Phase Separator'!E29 -> 0.51798561 | I17: ='Heater 3'!E12 -> 1 | K17: ='Heater 3'!O12 -> 1
A18: EO | C18: ='Heater 2'!I22 -> 1 | E18: ='Holding Tank'!E18 -> 1 | F18: =Reactor!F51 -> 1 | G18: ='Cooler 1'!E15 -> 0.13669065 | H18: ='Phase Separator'!E30 -> 0.13669065 | J18: ='Distillation Column 1 '!G24 -> 0.28358209 | L18: ='Cooler 2'!E14 -> 0.32629229 | P18: ='Liquid-liquid Extractor '!E27 -> 0.32629229 | R18: ='Heater 4'!J15 -> 1 | S18: ='Distillation Column 3'!E28 -> 0.0029931866 | T18: ='Distillation Column 3'!H60 -> 0.009696846 | V18: ='Holding Tank'!H48 -> 1
A19: MEA | G19: ='Cooler 1'!E16 -> 0.28776978 | H19: ='Phase Separator'!E31 -> 0.28776978 | J19: ='Distillation Column 1 '!G25 -> 0.59701493 | L19: ='Cooler 2'!E15 -> 0.67319251 | M19: ='Distillation Column 2'!E16 -> 0.091220068 | N19: ='Distillation Column 2'!H46 -> 0.18049915 | P19: ='Liquid-liquid Extractor '!E28 -> 0.67319251 | S19: ='Distillation Column 3'!E29 -> 0.30877082 | T19: ='Distillation Column 3'!H61 -> 0.99030315 | U19: ='Distillation Column 3'!L21 -> 0.0044663712
A20: DEA | G20: ='Cooler 1'!E17 -> 0.021582734 | H20: ='Phase Separator'!E32 -> 0.021582734 | J20: ='Distillation Column 1 '!G26 -> 0.044776119 | L20: ='Cooler 2'!E16 -> 0.00051519835 | M20: ='Distillation Column 2'!E17 -> 0.3386545 | N20: ='Distillation Column 2'!H47 -> 0.65 | O20: ='Distillation Column 2'!N17 -> 0.020540148 | P20: ='Liquid-liquid Extractor '!E29 -> 0.00051519835 | S20: ='Distillation Column 3'!E30 -> 0.0002363042 | U20: ='Distillation Column 3'!L22 -> 0.00034181412
A21: TEA | G21: ='Cooler 1'!E18 -> 0.035971223 | H21: ='Phase Separator'!E33 -> 0.035971223 | J21: ='Distillation Column 1 '!G27 -> 0.074626866 | M21: ='Distillation Column 2'!E18 -> 0.57012543 | N21: ='Distillation Column 2'!H48 -> 0.16950085 | O21: ='Distillation Column 2'!N18 -> 0.97945985
A22: EG | Q22: ='Liquid-liquid Extractor '!M28 -> 1 | S22: ='Distillation Column 3'!E32 -> 0.68799968 | U22: ='Distillation Column 3'!L24 -> 0.99519181
A23: Total Mole Fraction | B23: ='Heater 1'!J20 -> 1 | C23: ='Heater 2'!I28 -> 1 | D23: =Reactor!D28 -> 1 | E23: ='Holding Tank'!E24 -> 1 | F23: =Reactor!F57 -> 1 | G23: ='Cooler 1'!E21 -> 1 | H23: ='Phase Separator'!E36 -> 1 | I23: ='Heater 3'!E19 -> 1 | J23: ='Distillation Column 1 '!G30 -> 1 | K23: ='Heater 3'!O19 -> 1 | L23: ='Cooler 2'!E20 -> 1 | M23: ='Distillation Column 2'!E21 -> 1 | N23: ='Distillation Column 2'!H51 -> 1 | O23: ='Distillation Column 2'!N21 -> 1 | P23: ='Liquid-liquid Extractor '!E33 -> 1 | Q23: ='Liquid-liquid Extractor '!M30 -> 1 | R23: ='Heater 4'!J21 -> 1 | S23: ='Distillation Column 3'!E34 -> 1 | T23: ='Distillation Column 3'!H66 -> 1 | U23: ='Distillation Column 3'!L26 -> 1 | V23: ='Holding Tank'!H54 -> 1
A24: T (°C) | B24: ='Heater 1'!J21 -> 25 | C24: ='Heater 2'!I29 -> 25 | D24: =Reactor!D29 -> 350 | E24: ='Holding Tank'!E25 -> 350 | F24: =Reactor!F58 -> 350 | G24: ='Cooler 1'!E22 -> 350 | H24: ='Phase Separator'!E37 -> 10 | I24: ='Heater 3'!E20 -> 10 | J24: ='Distillation Column 1 '!G31 -> 10 | K24: ='Heater 3'!O20 -> 50 | L24: ='Cooler 2'!E21 -> 170 | M24: ='Distillation Column 2'!E22 -> 250 | N24: ='Distillation Column 2'!H52 -> 269 | O24: ='Distillation Column 2'!N22 -> 335 | P24: ='Liquid-liquid Extractor '!E34 -> 6 | Q24: ='Liquid-liquid Extractor '!M31 -> 6 | R24: ='Heater 4'!J22 -> 6 | S24: ='Distillation Column 3'!E35 -> 6 | T24: ='Distillation Column 3'!H67 -> 165 | U24: ='Distillation Column 3'!L27 -> 190 | V24: ='Holding Tank'!H55 -> 350
A25: P (atm) | B25: ='Heater 1'!J22 -> 1 | C25: ='Heater 2'!I30 -> 1 | D25: =Reactor!D30 -> 1 | E25: ='Holding Tank'!E26 -> 1 | F25: =Reactor!F59 -> 1 | G25: ='Cooler 1'!E23 -> 1 | H25: ='Phase Separator'!E38 -> 1 | I25: ='Heater 3'!E21 -> 1 | J25: ='Distillation Column 1 '!G32 -> 1 | K25: ='Heater 3'!O21 -> 1 | L25: ='Cooler 2'!E22 -> 1 | M25: ='Distillation Column 2'!E23 -> 1 | N25: ='Distillation Column 2'!H53 -> 1 | O25: ='Distillation Column 2'!N23 -> 1 | P25: ='Liquid-liquid Extractor '!E35 -> 1 | Q25: ='Liquid-liquid Extractor '!M32 -> 1 | R25: ='Heater 4'!J23 -> 1 | S25: ='Distillation Column 3'!E36 -> 1 | T25: ='Distillation Column 3'!H68 -> 1 | U25: ='Distillation Column 3'!L28 -> 1 | V25: ='Holding Tank'!H56 -> 1
A26: H (kJ/hr) | B26: ='Heater 1'!AA35 -> 0 | C26: ='Heater 2'!Y37 -> 0 | D26: =Reactor!T98 -> 5670422 | E26: ='Holding Tank'!S38 -> 4881461.5 | F26: =Reactor!V98 -> 6362282.8 | G26: ='Cooler 1'!R51 -> 12522338 | H26: ='Phase Separator'!T56 -> -15092871 | I26: ='Heater 3'!Z38 -> -138511.7 | J26: ='Distillation Column 1 '!U65 -> -14954359 | K26: ='Heater 3'!AB38 -> -4849643.8 | L26: ='Cooler 2'!U42 -> 2604648.3 | M26: ='Distillation Column 2'!Y64 -> -785407.13 | N26: ='Distillation Column 2'!AA64 -> -294328.48 | O26: ='Distillation Column 2'!AC64 -> 197749.9 | P26: ='Liquid-liquid Extractor '!T68 -> -11767908 | Q26: ='Liquid-liquid Extractor '!V68 -> -22289384 | R26: ='Heater 4'!T40 -> -1788296.9 | S26: ='Distillation Column 3'!W57 -> -32268995 | T26: ='Distillation Column 3'!Y57 -> -5321475.7 | U26: ='Distillation Column 3'!AA57 -> -12312097 | V26: ='Holding Tank'!U38 -> 1480821.3

Sheet Process Flow Diagram
AJ7: S8 | AQ7: S10
AG10: Total Mass Flowrate (kg/hr) | AI10: ='Heater 3'!E2 -> 4393.2102
AG11: Total Molar Flowrate (kmol/hr) | AI11: ='Heater 3'!E3 -> 257.95375 | AP11: Total Mass Flowrate (kg/hr) | AR11: ='Heater 3'!O2 -> 4393.2102
AG12: Components Molar Flowrate (kmol/hr) | AP12: Total Molar Flowrate (kmol/hr) | AR12: ='Heater 3'!O3 -> 257.95375
AG13: AM | AI13: ='Heater 3'!E5 -> 257.95375 | AP13: Components Molar Flowrate (kmol/hr)
AG14: EO | AP14: AM | AR14: ='Heater 3'!O5 -> 257.95375
AG15: MEA | AP15: EO
AG16: DEA | AP16: MEA
G17: S1 | N17: S3 | U17: S6 | AB17: S7 | AG17: TEA | AP17: DEA | BA17: S16
AG18: EG | AP18: TEA | BA18: Total Mass Flowrate (kg/hr) | BC18: ='Liquid-liquid Extractor '!M13 -> 19423.574
AG19: Molar Composition | AP19: EG | BA19: Total Molar Flowrate (kmol/hr) | BC19: ='Liquid-liquid Extractor '!M14 -> 312.93014
AG20: AM | AI20: ='Heater 3'!E12 -> 1 | AP20: Molar Composition | BA20: Components Molar Flowrate (kmol/hr)
E21: Total Mass Flowrate (kg/hr) | G21: ='Heater 1'!J3 -> 7322.0171 | L21: Total Mass Flowrate (kg/hr) | N21: =Reactor!D11 -> 7322.0171 | S21: Total Mass Flowrate (kg/hr) | U21: ='Cooler 1'!E4 -> 19948.09 | AA21: Total Mass Flowrate (kg/hr) | AC21: ='Phase Separator'!E19 -> 19948.09 | AG21: EO | AP21: AM | AR21: ='Heater 3'!O12 -> 1 | BA21: AM
E22: Total Molar Flowrate (kmol/hr) | G22: ='Heater 1'!J4 -> 429.92291 | L22: Total Molar Flowrate (kmol/hr) | N22: =Reactor!D12 -> 429.92291 | S22: Total Molar Flowrate (kmol/hr) | U22: ='Cooler 1'!E5 -> 497.99404 | AA22: Total Molar Flowrate (kmol/hr) | AC22: ='Phase Separator'!E20 -> 497.99404 | AG22: MEA | AP22: EO | BA22: EO | BQ22: S20
E23: Components Molar Flowrate (kmol/hr) | L23: Components Molar Flowrate (kmol/hr) | S23: Components Molar Flowrate (kmol/hr) | AA23: Components Molar Flowrate (kmol/hr) | AG23: DEA | AP23: MEA | BA23: MEA
E24: AM | F24: ṅ3 | G24: ='Heater 1'!J6 -> 429.92291 | L24: AM | M24: ṅ3 | N24: =Reactor!D14 -> 429.92291 | S24: AM | T24: ṅ6a | U24: ='Cooler 1'!E7 -> 257.95375 | AA24: AM | AB24: ṅ6a | AC24: ='Phase Separator'!E22 -> 257.95375 | AG24: TEA | AP24: DEA | BA24: DEA
E25: EO | L25: EO | S25: EO | T25: ṅ6b | U25: ='Cooler 1'!E8 -> 68.071127 | AA25: EO | AB25: ṅ6b | AC25: ='Phase Separator'!E23 -> 68.071127 | AG25: EG | AP25: TEA | BA25: TEA | BP25: Total Mass Flowrate (kg/hr) | BR25: ='Distillation Column 3'!L9 -> 19520.66
E26: MEA | L26: MEA | S26: MEA | T26: ṅ6c | U26: ='Cooler 1'!E9 -> 143.30764 | AA26: MEA | AB26: ṅ6c | AC26: ='Phase Separator'!E24 -> 143.30764 | AG26: Vapour Fraction | AI26: ='Heater 3'!E18 -> 1 | AP26: EG | BA26: EG | BB26: ṅ16 | BC26: ='Liquid-liquid Extractor '!M21 -> 312.93014 | BP26: Total Molar Flowrate (kmol/hr) | BR26: ='Distillation Column 3'!L10 -> 314.44203
E27: DEA | L27: DEA | S27: DEA | T27: ṅ6d | U27: ='Cooler 1'!E10 -> 10.748073 | AA27: DEA | AB27: ṅ6d | AC27: ='Phase Separator'!E25 -> 10.748073 | AG27: Total Mole Fraction | AI27: ='Heater 3'!E19 -> 1 | AP27: Vapour Fraction | AR27: ='Heater 3'!O18 -> 0 | BA27: Molar Composition | BP27: Components Molar Flowrate (kmol/hr)
E28: TEA | L28: TEA | S28: TEA | T28: ṅ6e | U28: ='Cooler 1'!E11 -> 17.913455 | AA28: TEA | AB28: ṅ6e | AC28: ='Phase Separator'!E26 -> 17.913455 | AG28: T (°C) | AI28: ='Heater 3'!E20 -> 10 | AP28: Total Mole Fraction | AR28: ='Heater 3'!O19 -> 1 | BA28: AM | BP28: AM
E29: EG | L29: EG | S29: EG | AA29: EG | AG29: P (atm) | AI29: ='Heater 3'!E21 -> 1 | AP29: T (°C) | AR29: ='Heater 3'!O20 -> 50 | BA29: EO | BP29: EO
E30: Molar Composition | L30: Molar Composition | S30: Molar Composition | AA30: Molar Composition | AG30: H (kJ/hr) | AI30: ='Heater 3'!E22 -> -138511.7 | AP30: P (atm) | AR30: ='Heater 3'!O21 -> 1 | BA30: MEA | BP30: MEA | BQ30: ṅ20a | BR30: ='Distillation Column 3'!L14 -> 1.4044148
E31: AM | G31: ='Heater 1'!$J$13 -> 1 | L31: AM | N31: =Reactor!D21 -> 1 | S31: AM | U31: ='Cooler 1'!E14 -> 0.51798561 | AA31: AM | AC31: ='Phase Separator'!E29 -> 0.51798561 | AP31: H (kJ/hr) | AR31: ='Heater 3'!O22 -> -4849643.8 | BA31: DEA | BJ31: x | BP31: DEA | BQ31: ṅ20b | BR31: ='Distillation Column 3'!L15 -> 0.10748073
E32: EO | L32: EO | S32: EO | U32: ='Cooler 1'!E15 -> 0.13669065 | AA32: EO | AC32: ='Phase Separator'!E30 -> 0.13669065 | BA32: TEA | BP32: TEA
E33: MEA | L33: MEA | S33: MEA | U33: ='Cooler 1'!E16 -> 0.28776978 | AA33: MEA | AC33: ='Phase Separator'!E31 -> 0.28776978 | BA33: EG | BC33: ='Liquid-liquid Extractor '!M28 -> 1 | BP33: EG | BQ33: ṅ20c | BR33: ='Distillation Column 3'!L17 -> 312.93014
E34: DEA | L34: DEA | S34: DEA | U34: ='Cooler 1'!E17 -> 0.021582734 | AA34: DEA | AC34: ='Phase Separator'!E32 -> 0.021582734 | BA34: Vapour Fraction | BC34: ='Liquid-liquid Extractor '!M29 -> 0 | BP34: Molar Composition
E35: TEA | L35: TEA | S35: TEA | U35: ='Cooler 1'!E18 -> 0.035971223 | AA35: TEA | AC35: ='Phase Separator'!E33 -> 0.035971223 | BA35: Total Mole Fraction | BC35: ='Liquid-liquid Extractor '!M30 -> 1 | BP35: AM
E36: EG | L36: EG | S36: EG | AA36: EG | BA36: T (°C) | BC36: ='Liquid-liquid Extractor '!M31 -> 6 | BP36: EO
E37: Vapour Fraction | G37: ='Heater 1'!$J$19 -> 1 | L37: Vapour Fraction | N37: =Reactor!D27 -> 1 | S37: Vapour Fraction | U37: ='Cooler 1'!E20 -> 1 | AA37: Vapour Fraction | AC37: ='Phase Separator'!E35 -> 0.51798561 | BA37: P (atm) | BC37: ='Liquid-liquid Extractor '!M32 -> 1 | BP37: MEA | BR37: ='Distillation Column 3'!L21 -> 0.0044663712
E38: Total Mole Fraction | G38: ='Heater 1'!$J$20 -> 1 | L38: Total Mole Fraction | N38: =Reactor!D28 -> 1 | S38: Total Mole Fraction | U38: ='Cooler 1'!E21 -> 1 | AA38: Total Mole Fraction | AC38: ='Phase Separator'!E36 -> 1 | BA38: H (kJ/hr) | BC38: ='Liquid-liquid Extractor '!M33 -> -22289384 | BP38: DEA | BR38: ='Distillation Column 3'!L22 -> 0.00034181412
E39: T (°C) | G39: ='Heater 1'!$J$21 -> 25 | L39: T (°C) | N39: =Reactor!D29 -> 350 | S39: T (°C) | U39: ='Cooler 1'!E22 -> 350 | AA39: T (°C) | AC39: ='Phase Separator'!E37 -> 10 | BP39: TEA
E40: P (atm) | G40: ='Heater 1'!$J$22 -> 1 | L40: P (atm) | N40: =Reactor!D30 -> 1 | S40: P (atm) | U40: ='Cooler 1'!E23 -> 1 | AA40: P (atm) | AC40: ='Phase Separator'!E38 -> 1 | BP40: EG | BR40: ='Distillation Column 3'!L24 -> 0.99519181
E41: H (kJ/hr) | G41: ='Heater 1'!J23 -> 0 | L41: H (kJ/hr) | N41: =Reactor!D31 -> 5670422 | S41: H (kJ/hr) | U41: ='Cooler 1'!E24 -> 12522338 | AA41: H (kJ/hr) | AC41: ='Phase Separator'!E39 -> -15092871 | AO41: S11 | AU41: S15 | BI41: S18 | BP41: Vapour Fraction | BR41: ='Distillation Column 3'!$L$25 -> 0
BP42: Total Mole Fraction | BR42: ='Distillation Column 3'!$L$26 -> 1
S43: S5 | BP43: T (°C) | BR43: ='Distillation Column 3'!$L$27 -> 190
S44: Total Mass Flowrate (kg/hr) | U44: =Reactor!F40 -> 12626.263 | AM44: Total Mass Flowrate (kg/hr) | AO44: ='Cooler 2'!$E$3 -> 11588.625 | AT44: Total Mass Flowrate (kg/hr) | AV44: ='Liquid-liquid Extractor '!E16 -> 11588.625 | BH44: Total Mass Flowrate (kg/hr) | BJ44: ='Distillation Column 3'!E17 -> 28073.436 | BP44: P (atm) | BR44: ='Distillation Column 3'!$L$28 -> 1
S45: Total Molar Flowrate (kmol/hr) | U45: =Reactor!F41 -> 286.61527 | AM45: Total Molar Flowrate (kmol/hr) | AO45: ='Cooler 2'!$E$4 -> 208.62009 | AT45: Total Molar Flowrate (kmol/hr) | AV45: ='Liquid-liquid Extractor '!E17 -> 208.62009 | BH45: Total Molar Flowrate (kmol/hr) | BJ45: ='Distillation Column 3'!E18 -> 454.84052 | BP45: H (kJ/hr) | BR45: ='Distillation Column 3'!L29 -> -12312097
S46: Components Molar Flowrate (kmol/hr) | AM46: Components Molar Flowrate (kmol/hr) | AT46: Components Molar Flowrate (kmol/hr) | BH46: Components Molar Flowrate (kmol/hr)
S47: AM | AM47: AM | AT47: AM | BH47: AM
S48: EO | T48: ṅ5 | U48: =Reactor!F44 -> 286.61527 | AM48: EO | AN48: ṅ11a | AO48: ='Cooler 2'!$E$7 -> 68.071127 | AT48: EO | AU48: ='Cooler 2'!M7 -> ṅ15a | AV48: ='Liquid-liquid Extractor '!E20 -> 68.071127 | BH48: EO | BI48: ṅ18a | BJ48: ='Distillation Column 3'!E21 -> 1.3614225
...

Sheet Conversion 
B3: Conversion of 100,000 metric tonnes of Ethylene Oxide (EO) per year:
B5: 0.001 | C5: metric ton (tonne) | D5: = | E5: 1 | F5: kg
B6: 1 | C6: kmol C₂H₄O | D6: = | E6: 44.053 | F6: kg C₂H₄O
B7: 1 | C7: year | D7: = | E7: 330 | F7: days
B8: 1 | C8: day | D8: = | E8: 24 | F8: hours
B12: Basis: 100,000 metric tonnes of EO entering the reactor
B14: 100000 | C14: metric tonnes C₂H₄O | D14: 1 | E14: kg C₂H₄O | F14: 1 | G14: kmol C₂H₄O | H14: 1 | I14: year | J14: 1 | K14: day | L14: = | M14: =B14/(D15*F15*H15*J15) -> 286.61527 | N14: kmol/hr EO
B15: year | D15: 0.001 | E15: metric tonnes C₂H₄O | F15: 44.053 | G15: kg C₂H₄O | H15: 330 | I15: days | J15: 24 | K15: hours

Sheet Database
I2: Source: i. Textbook: Felder's Elementary Principles of Chemical Process Global Edition
I3: ii. Chemical Properties Handbook: Physical, Thermodynamic, Environmental, Transport, Safety, and Health Related Properties for Organic and Inorganic Chemicals
I4: iii. Link: https://www.chemeo.com/cid/20-170-0/Monoethanolamine
I5: iv. Link: https://www.chemeo.com/cid/30-006-1/Diethanolamine
I6: v. Link: https://www.chemeo.com/cid/64-895-8/Triethanolamine
B7: Table 1.1: Physical Properties Data | I7: vi. Link: https://webbook.nist.gov/cgi/cbook.cgi?ID=C107211&Mask=1EFF
B9: Substance | C9: Formula | D9: Symbol | E9: Mol. Wt. (g/mol) | F9: Tm (K) | G9: ∆Ĥm (kJ/mol) | H9: Tb (K) | I9: ∆Ĥv (kJ/mol) | J9: Tc (K) | K9: Pc (bar) | L9: Standard ∆Ĥf,v (kJ/mol) | M9: Standard ∆Ĥf (kJ/mol)
B10: Ammonia | C10: NH₃ | D10: AM | E10: 17.03 | F10: 195.35 | G10: 5.653 | H10: 239.72 | I10: 23.351 | J10: 405.5 | K10: 112.77473 | L10: -46.19 | M10: -67.2 (l)
B11: Ethylene oxide | C11: C₂H₄O | D11: EO | E11: 44.053 | F11: 161.45 | G11: 5.171 | H11: 283.85 | I11: Table 1.2 | J11: 469.15 | K11: 71.94 | L11: -52.63 | M11: -95.7 (l)
B12: Monoethanolamine | C12: C₂H₇NO | D12: MEA | E12: 61.084 | F12: 283.65 | G12: 10.22 | H12: 444.15 | J12: 638 | K12: 68.7 | L12: -203.05 | M12: -507.50 (l)
B13: Diethanolamine | C13: C₄H₁₁NO₂ | D13: DEA | E13: 105.1356 | F13: 301.15 | G13: 19.39 | H13: 542.04 | J13: 715 | K13: 32.7 | L13: -397.1 | M13: -493.80 (s)
B14: Triethanolamine | C14: C₆H₁₅NO₃ | D14: TEA | E14: 149.19 | F14: 294.35 | G14: 26.58 | H14: =335.4+273.15 -> 608.55 | J14: 787 | K14: 24.5 | L14: -558.3 | M14: -664.20 (l)
B15: Ethylene glycol | C15: C₂H₆O₂ | D15: EG | E15: 62.07 | F15: 260.15 | G15: 9.958 | H15: 470.35 | J15: 744.6 | K15: 46 | L15: -387.1 | M15: -451.50 (l)
B16: Therminol VP-1 | C16: 73.5% C12H10O & 26.5% C12H10 | D16: TVP | E16: =166 -> 166 | F16: - | G16: - | H16: =530.15 -> 530.15 | I16: =294.2995 -> 294.2995 | J16: - | K16: - | L16: - | M16: -
I17: (in kJ/kg)
B18: Table 1.2: Enthalpy of Vaporization Data | F18: Formula： | I18: Source: i. Chemical Properties Handbook: Physical, Thermodynamic, Environmental, Transport, Safety, and Health Related Properties for Organic and Inorganic Chemicals
B20: Substance | C20: A | D20: Tc (K) | E20: n | F20: Tmin (K) | G20: Tmax (K) | H20: Tb (K) | I20: Ĥv at Tb (kJ/ mol)
B21: Ethylene oxide | C21: 36.474 | D21: 469.15 | E21: 0.377 | F21: 160.71 | G21: 469.15 | H21: 283.85 | I21: 25.7
B22: Monoethanolamine | C22: 74.024 | D22: 638 | E22: 0.304 | F22: 283.65 | G22: 638 | H22: 444.15 | I22: 51.53
B23: Diethanolamine | C23: 103.4 | D23: 715 | E23: 0.333 | F23: 301.15 | G23: 715 | H23: 542.04 | I23: 64.46
B24: Triethanolamine | C24: 120.6 | D24: 787 | E24: 0.354 | F24: 294.35 | G24: 787 | H24: =335.4+273.15 -> 608.55 | I24: 70.68
B25: Ethylene glycol | C25: 88.2 | D25: 645 | E25: 0.397 | F25: 260.15 | G25: 645 | H25: 470.35 | I25: 56.9
B28: Table 1.3: Heat Capacity of Gas Data | E28: Formula: | I28: Source: i. Chemical Properties Handbook: Physical, Thermodynamic, Environmental, Transport, Safety, and Health Related Properties for Organic and Inorganic Chemicals
B30: Substance | C30: A | D30: B | E30: C | F30: D | G30: E | H30: F | I30: Tmin (K) | J30: Tmax (K)
B31: Ammonia | C31: 33.573 | D31: -0.012581 | E31: 8.8906e-05 | F31: -7.1783e-08 | G31: 1.8569e-11 | H31: - | I31: 100 | J31: 1500
B32: Ethylene oxide | C32: 30.827 | D32: =-0.0076041 -> -0.0076041 | E32: =0.00032347 -> 0.00032347 | F32: =-0.00000032747 -> -3.2747e-07 | G32: =0.000000000097271 -> 9.7271e-11 | H32: - | I32: 50 | J32: 1500
B33: Monoethanolamine | C33: -0.555 | D33: 0.37003 | E33: -0.00031976 | F33: 1.5834e-07 | G33: -3.2344e-11 | H33: - | I33: 298 | J33: 1500
B34: Diethanolamine | C34: -5.264 | D34: 0.61929 | E34: -0.00049545 | F34: 2.1789e-07 | G34: -3.8987e-11 | H34: - | I34: 298 | J34: 1500
B35: Triethanolamine | C35: 37.73 | D35: 0.49155 | E35: 0.00035952 | F35: -8.2287e-07 | G35: 3.5374e-10 | H35: - | I35: 298 | J35: 1200
B36: Ethylene glycol | C36: 48.218 | D36: 0.19073 | E36: -6.6117e-05 | F36: -1.8834e-08 | G36: 1.2555e-11 | H36: - | I36: 200 | J36: 1500
B37: Therminol VP-1 (kJ/kg.K) | C37: =-5.426*(10^3) -> -5426 | D37: =62.48 -> 62.48 | E37: =-0.2532 -> -0.2532 | F37: =5.432*(10^-4) -> 0.0005432 | G37: =-5.842*(10^-7) -> -5.842e-07 | H37: =2.508*(10^-10) -> 2.508e-10 | I37: - | J37: -
B40: Table 1.4: Heat Capacity of Liquid Data | E40: Formula: | I40: Source: i. Chemical Properties Handbook: Physical, Thermodynamic, Environmental, Transport, Safety, and Health Related Properties for Organic and Inorganic Chemicals
B42: Substance | C42: A | D42: B | E42: C | F42: D | G42: Tmin | H42: Tmax | I42: Cp (J/ mol.K ) at 25°C
B43: Ammonia | C43: -182.157 | D43: 3.3618 | E43: -0.014398 | F43: 2.0371e-05 | G43: 195 | H43: 385 | I43: 80.16
B44: Ethylene oxide | C44: 35.72 | D44: 0.42908 | E44: -0.0015473 | F44: 2.407e-06 | G44: 162 | H44: 422 | I44: 89.9
B45: Monoethanolamine | C45: 23.111 | D45: 1.2283 | E45: -0.0031218 | F45: 3.0714e-06 | G45: 285 | H45: 574 | I45: 193.21
B46: Diethanolamine | C46: 76.703 | D46: 1.0821 | E46: -0.002486 | F46: 2.2497e-06 | G46: 302 | H46: 644 | I46: -
B47: Triethanolamine | C47: 179.047 | D47: 1.2436 | E47: -0.0026631 | F47: 2.3379e-06 | G47: 295 | H47: 708 | I47: 375.06
B48: Ethylene glycol | C48: 75.878 | D48: 0.64182 | E48: -0.0016493 | F48: 1.6937e-06 | G48: 261 | H48: 581 | I48: 165.52
B49: Therminol VP-1 (kJ/kg.K) | C49: 382.11 | D49: =4.342 -> 4.342 | E49: -0.00145 | F49: - | G49: - | H49: - | I49: 2.128 | J49: (in kJ/kg.K)
...

Sheet Reactor
F2: C₂H₄O (v) + NH₃ (v) → C₂H₇NO (v) (Main reaction) | K2: ζ₁
F3: C₂H₇NO (v) + C₂H₄O (v) → C₄H₁₁NO₂ (v) (Side reaction 1) | K3: ζ ₂
F4: C₄H₁₁NO₂ (v) + C₂H₄O (v) → C₆H₁₅NO₃ (v) (Side reaction 2) | K4: ζ ₃ | P4: Components | Q4: Molecular Weight (kg/kmol) | S4: Degree of Freedom Analysis (Extent of Reaction)
P5: NH₃ (AM) | Q5: =17.031 -> 17.031 | S5: No. unkown labeled variable = | T5: 6 | U5: ( ṅ3,ṅ5,ṅ6a,ṅ6b,ṅ6c,ṅ6d,ṅ6e)
P6: C₂H₄O (EO) | Q6: 44.053 | S6: No. independent reactions = | T6: 3 | U6: ( ζ₁ , ζ ₂ , ζ ₃ )
P7: C₂H₇NO (MEA) | Q7: 61.083 | S7: No. independent reactive species = | T7: -5 | U7: (MEA, DEA, TEA, AM, EO)
P8: C₄H₁₁NO₂ (DEA) | Q8: 105.136 | S8: No. independent non-reactive species = | T8: 0
P9: C₆H₁₅NO₃ (TEA) | Q9: 149.188 | S9: No. process specification equation = | T9: -4 | U9: Ps (① fcon EO main = 60%
P10: C₂H₆O₂ (EG) | Q10: 62.07 | U10: ② fcon EO side 1 = 10%
B11: Total Mass Flowrate (kg/hr) | D11: =Q5*D14 -> 7322.0171 | U11: ③ selectivity of MEA over TEA= 8
B12: Total Molar Flowrate (kmol/hr) | D12: =D14 -> 429.92291 | U12: ④ fexcess AM = 50% )
B13: Components Molar Flowrate (kmol/hr) | T13: =SUM(T5:T12) -> 0 | U13: can be solved
B14: AM | C14: ṅ3 | D14: =U43 -> 429.92291
B15: EO
B16: MEA | S16: Ps ①
B17: DEA | S17: fcon EO main = 60%
B18: TEA | S18: ζ₁ | T18: = | U18: =60% -> 0.6
B19: EG | S19: 286.6348
B20: Molar Composition | S20: ζ₁ | T20: = | U20: =U18*F44 -> 171.96916 | V20: kmol/hr
B21: AM | D21: =D14/$D$12 -> 1
B22: EO
B23: MEA | S23: Ps ②
B24: DEA | S24: fcon EO side 1 = 10%
B25: TEA | F25: Conversion of EO = 60% (Main reaction) | S25: ζ ₂ | T25: = | U25: =10% -> 0.1
B26: EG | F26: Conversion of EO = 10% (Side reaction 1) | S26: 286.6348
B27: Vapour Fraction | D27: 1 | F27: Selectivity of MEA over TEA = 8 kmol/kmol | S27: ζ ₂ | T27: = | U27: =U25*F44 -> 28.661527 | V27: kmol/hr
B28: Total Mole Fraction | D28: =SUM(D21) -> 1 | F28: % excess of AM = 50%
B29: T (°C) | D29: 350 | S29: Ps ③
B30: P (atm) | D30: 1 | S30: ṅ6c | T30: = | U30: 8
B31: H (kJ/hr) | D31: =T98 -> 5670422 | S31: ṅ6e
N32: S6 | S32: ṅ6c | T32: = | U32: 8ṅ6e
E33: S3 | S33: ṅ6c | T33: = | U33: 8ζ ₃ | V33: (1)
S35: Ps ④
K36: Total Mass Flowrate (kg/hr) | M36: =M39*Q5+M40*Q6+M41*Q7+Q8*M42+M43*Q9 -> 19948.09 | S36: fexcess AM = 0.5
K37: Total Molar Flowrate (kmol/hr) | M37: =SUM(M39:M43) -> 497.99404 | S37: =F44 -> 286.61527 | T37: kmol of EO fed | U37: 1 | V37: mol of AM reacted
G38: S5 | K38: Components Molar Flowrate (kmol/hr) | S38: hr | U38: 1 | V38: mol of EO reacted
K39: AM | L39: ṅ6a | M39: =U61 -> 257.95375 | S39: = | T39: =S37*(U37/U38) -> 286.61527 | U39: kmol of AM reacted / hr
D40: Total Mass Flowrate (kg/hr) | F40: =Q6*F44 -> 12626.263 | K40: EO | L40: ṅ6b | M40: =U75 -> 68.071127
D41: Total Molar Flowrate (kmol/hr) | F41: =F44 -> 286.61527 | K41: MEA | L41: ṅ6c | M41: =U48 -> 143.30764 | S41: ṅ3 - 286.6348 | T41: = | U41: =50% -> 0.5
D42: Components Molar Flowrate (kmol/hr) | K42: DEA | L42: ṅ6d | M42: =U66 -> 10.748073 | S42: =T39 -> 286.61527
...

Sheet Cooler 1
Q3: Components | R3: Molecular Weight (kg/kmol) | T3: Degree of Freedom Analysis
C4: Total Mass Flowrate (kg/hr) | E4: =E7*R4+E8*R5+E9*R6+E10*R7+E11*R8 -> 19948.09 | L4: Total Mass Flowrate (kg/hr) | N4: =N7*R4+N8*R5+N9*R6+N10*R7+N11*R8 -> 19948.09 | Q4: NH₃ (AM) | R4: =17.031 -> 17.031 | T4: No. unkown labeled variable = | U4: 5 | V4: (ṅ7a, ṅ7b, ṅ7c, ṅ7d, ṅ7e)
C5: Total Molar Flowrate (kmol/hr) | E5: =SUM(E7:E12) -> 497.99404 | L5: Total Molar Flowrate (kmol/hr) | N5: =SUM(N7:N11) -> 497.99404 | Q5: C₂H₄O (EO) | R5: 44.053 | T5: No. material balance spesies = | U5: -5 | V5: (AM, EO, MEA, DEA, TEA)
C6: Components Molar Flowrate (kmol/hr) | L6: Components Molar Flowrate (kmol/hr) | Q6: C₂H₇NO (MEA) | R6: 61.083 | T6: No. process specification equation = | U6: 0 | V6: Ps
C7: AM | D7: ṅ6a | E7: =Reactor!M39 -> 257.95375 | L7: AM | M7: ṅ7a | N7: =V11 -> 257.95375 | Q7: C₄H₁₁NO₂ (DEA) | R7: 105.136 | U7: =SUM(U4:U6) -> 0 | V7: can be solved
C8: EO | D8: ṅ6b | E8: =Reactor!M40 -> 68.071127 | L8: EO | M8: ṅ7b | N8: =V15 -> 68.071127 | Q8: C₆H₁₅NO₃ (TEA) | R8: 149.188
C9: MEA | D9: ṅ6c | E9: =Reactor!M41 -> 143.30764 | L9: MEA | M9: ṅ7c | N9: =V19 -> 143.30764 | Q9: C₂H₆O₂ (EG) | R9: 62.07 | T9: AM Balance ( in=out )
C10: DEA | D10: ṅ6d | E10: =Reactor!M42 -> 10.748073 | L10: DEA | M10: ṅ7d | N10: =V23 -> 10.748073 | T10: ṅ6a | U10: = | V10: ṅ7a
C11: TEA | D11: ṅ6e | E11: =Reactor!M43 -> 17.913455 | L11: TEA | M11: ṅ7e | N11: =V27 -> 17.913455 | T11: ṅ7a | U11: = | V11: =E7 -> 257.95375 | W11: kmol / hr AM
C12: EG | L12: EG
C13: Molar Composition | L13: Molar Composition | T13: EO Balance (in=out )
C14: AM | E14: =E7/$E$5 -> 0.51798561 | L14: AM | N14: =N7/$N$5 -> 0.51798561 | T14: ṅ6b | U14: = | V14: ṅ7b
C15: EO | E15: =E8/$E$5 -> 0.13669065 | L15: EO | N15: =N8/$N$5 -> 0.13669065 | T15: ṅ7b | U15: = | V15: =E8 -> 68.071127 | W15: kmol / hr EO
C16: MEA | E16: =E9/$E$5 -> 0.28776978 | L16: MEA | N16: =N9/$N$5 -> 0.28776978
C17: DEA | E17: =E10/$E$5 -> 0.021582734 | L17: DEA | N17: =N10/$N$5 -> 0.021582734 | T17: MEA Balance ( in=out )
C18: TEA | E18: =E11/$E$5 -> 0.035971223 | L18: TEA | N18: =N11/$N$5 -> 0.035971223 | T18: ṅ6c | U18: = | V18: ṅ7c
C19: EG | L19: EG | T19: ṅ7c | U19: = | V19: =E9 -> 143.30764 | W19: kmol / hr MEA
C20: Vapour Fraction | E20: 1 | L20: Vapour Fraction | N20: =N14 -> 0.51798561
C21: Total Mole Fraction | E21: =SUM(E14:E19) -> 1 | L21: Total Mole Fraction | N21: =SUM(N14:N19) -> 1 | T21: DEA Balance ( in=out )
C22: T (°C) | E22: 350 | L22: T (°C) | N22: ='Answer Table'!H24 -> 10 | T22: ṅ6d | U22: = | V22: ṅ7d
C23: P (atm) | E23: 1 | L23: P (atm) | N23: ='Answer Table'!H25 -> 1 | T23: ṅ7d | U23: = | V23: =E10 -> 10.748073 | W23: kmol / hr DEA
C24: H (kJ/hr) | E24: =R51 -> 12522338 | L24: H (kJ/hr) | N24: =T51 -> -15092871
B25: S6 | O25: S7 | T25: TEA Balance ( in=out )
T26: ṅ6e | U26: = | V26: ṅ7e
T27: ṅ7e | U27: = | V27: =E11 -> 17.913455 | W27: kmol / hr TEA
Q30: Energy Balance
Q31: ΔĖp + ΔĖk + ΔḢ = Q̇ + Ẇs
Q33: Assumptions:
Q34: 1 | R34: There is no changes in elevation of height in each unit system, ΔĖp = 0
Q35: 2 | R35: There is no changes in velocity in each unit system, ΔĖk = 0
Q36: 3 | R36: There is no moving parts in each unit system, Ẇs = 0
Q38: Reference state: | R38: AM,EO,MEA,DEA,TEA,(v, | T38: 25 | U38: °C, 1 atm)
Q39: Substance | R39: Stream 6 | T39: Stream 7
R40: ṅ in (kmol/hr) | S40: Ĥ in (kJ/kmol) | T40: ṅ out (kmol/hr) | U40: Ĥ out (kJ/kmol)
Q41: AM (v） | R41: =E7 -> 257.95375 | S41: =S60 -> 13189.393 | T41: =N7 -> 257.95375 | U41: =S96 -> -536.96332
Q42: EO (v） | R42: =E8 -> 68.071127 | S42: =S67 -> 22197.989 | T42: - | U42: -
Q43: MEA (v） | R43: =E9 -> 143.30764 | S43: =S74 -> 37314.059 | T43: - | U43: -
Q44: DEA (v) | R44: =E10 -> 10.748073 | S44: =S81 -> 62487.219 | T44: - | U44: -
Q45: TEA (v) | R45: =E11 -> 17.913455 | S45: =S88 -> 88762.104 | T45: - | U45: -
Q46: EO (l) | R46: - | S46: - | T46: =N8 -> 68.071127 | U46: =S118 -> -26456.981
...

Sheet Phase Separator
J2: Total Mass Flowrate (kg/hr) | L2: =L5*Q5 -> 4393.2102
J3: Total Molar Flowrate (kmol/hr) | L3: =SUM(L5:L10) -> 257.95375
J4: Components Molar Flowrate (kmol/hr) | P4: Components | Q4: Molecular Weight (kg/kmol) | S4: Degree of Freedom Analysis
J5: AM | K5: ṅ8 | L5: =U13 -> 257.95375 | P5: NH₃ (AM) | Q5: =17.031 -> 17.031 | S5: No. unkown labeled variable = | T5: 5 | U5: (ṅ8, ṅ9a, ṅ9b, ṅ9c, ṅ9d)
J6: EO | P6: C₂H₄O (EO) | Q6: 44.053 | S6: No. material balance spesies = | T6: -5 | U6: (AM, EO, MEA, DEA, TEA)
J7: MEA | P7: C₂H₇NO (MEA) | Q7: 61.083 | S7: No. process specification equation = | T7: 0 | U7: Ps
J8: DEA | P8: C₄H₁₁NO₂ (DEA) | Q8: 105.136 | T8: =SUM(T5:T7) -> 0 | U8: can be solved
J9: TEA | P9: C₆H₁₅NO₃ (TEA) | Q9: 149.188
J10: EG | P10: C₂H₆O₂ (EG) | Q10: 62.07 | S10: AM Balance ( in=out )
J11: Molar Composition | S11: ṅ7a | T11: = | U11: ṅ8
J12: AM | L12: =L5/$L$3 -> 1 | S12: =E22 -> 257.95375 | T12: = | U12: ṅ8
J13: EO | S13: ṅ8 | T13: = | U13: =S12 -> 257.95375 | V13: kmol / hr AM
J14: MEA
J15: DEA | S15: EO Balance (in=out )
J16: TEA | S16: ṅ7b | T16: = | U16: ṅ9a
J17: EG | S17: =E23 -> 68.071127 | T17: = | U17: ṅ9a
J18: Vapour Fraction | L18: 1 | S18: ṅ9a | T18: = | U18: =S17 -> 68.071127 | V18: kmol / hr EO
C19: Total Mass Flowrate (kg/hr) | E19: =E22*Q5+E23*Q6+E24*Q7+E25*Q8+E26*Q9 -> 19948.09 | J19: Total Mole Fraction | L19: =SUM(L12:L17) -> 1
C20: Total Molar Flowrate (kmol/hr) | E20: =SUM(E22:E27) -> 497.99404 | J20: T (°C) | L20: 10 | S20: MEA Balance ( in=out )
C21: Components Molar Flowrate (kmol/hr) | J21: P (atm) | L21: 1 | S21: ṅ7c | U21: ṅ9b
C22: AM | D22: ṅ7a | E22: ='Cooler 1'!N7 -> 257.95375 | J22: H (kJ/hr) | L22: =V56 -> -138511.7 | S22: =E24 -> 143.30764 | T22: = | U22: ṅ9b
C23: EO | D23: ṅ7b | E23: ='Cooler 1'!N8 -> 68.071127 | S23: ṅ9b | T23: = | U23: =S22 -> 143.30764 | V23: kmol / hr MEA
C24: MEA | D24: ṅ7c | E24: ='Cooler 1'!N9 -> 143.30764 | N24: S8
C25: DEA | D25: ṅ7d | E25: ='Cooler 1'!N10 -> 10.748073 | S25: DEA Balance ( in=out )
C26: TEA | D26: ṅ7e | E26: ='Cooler 1'!N11 -> 17.913455 | S26: ṅ7d | T26: =
C27: EG | S27: =E25 -> 10.748073 | T27: = | U27: ṅ9c
C28: Molar Composition | S28: ṅ9c | T28: = | U28: =S27 -> 10.748073 | V28: kmol / hr DEA
C29: AM | E29: =E22/$E$20 -> 0.51798561
C30: EO | E30: =E23/$E$20 -> 0.13669065 | S30: TEA Balance ( in=out )
C31: MEA | E31: =E24/$E$20 -> 0.28776978 | S31: ṅ7e | T31: = | U31: ṅ9d
C32: DEA | E32: =E25/$E$20 -> 0.021582734 | S32: =E26 -> 17.913455 | T32: = | U32: ṅ9d
C33: TEA | E33: =E26/$E$20 -> 0.035971223 | S33: ṅ9d | T33: = | U33: =S32 -> 17.913455 | V33: kmol / hr TEA
C34: EG
C35: Vapour Fraction | E35: =E29 -> 0.51798561 | S35: Energy Balance
C36: Total Mole Fraction | E36: =SUM(E29:E34) -> 1 | S36: ΔĖp + ΔĖk + ΔḢ = Q̇ + Ẇs
C37: T (°C) | E37: 10
B38: S7 | C38: P (atm) | E38: 1 | S38: Assumptions:
C39: H (kJ/hr) | E39: =T56 -> -15092871 | S39: 1 | T39: There is no changes in elevation of height in each unit system, ΔĖp = 0
S40: 2 | T40: There is no changes in velocity in each unit system, ΔĖk = 0
S41: 3 | T41: There is no moving parts in each unit system, Ẇs = 0
...

Sheet Heater 3
C2: Total Mass Flowrate (kg/hr) | E2: =E5*W7 -> 4393.2102 | M2: Total Mass Flowrate (kg/hr) | O2: =O5*W7 -> 4393.2102
C3: Total Molar Flowrate (kmol/hr) | E3: =SUM(E5:E10) -> 257.95375 | M3: Total Molar Flowrate (kmol/hr) | O3: =SUM(O5:O10) -> 257.95375
C4: Components Molar Flowrate (kmol/hr) | M4: Components Molar Flowrate (kmol/hr)
C5: AM | D5: ṅ8 | E5: ='Phase Separator'!L5 -> 257.95375 | M5: AM | N5: ṅ10 | O5: =AA14 -> 257.95375
C6: EO | M6: EO | V6: Components | W6: Molecular Weight (kg/kmol) | Y6: Degree of Freedom Analysis
C7: MEA | M7: MEA | V7: NH₃ (AM) | W7: =17.031 -> 17.031 | Y7: No. unkown labeled variable = | Z7: 1 | AA7: (ṅ10)
C8: DEA | M8: DEA | V8: C₂H₄O (EO) | W8: 44.053 | Y8: No. material balance spesies = | Z8: -1 | AA8: (AM)
C9: TEA | M9: TEA | V9: C₂H₇NO (MEA) | W9: 61.083 | Y9: No. process specification equation = | Z9: 0 | AA9: Ps
C10: EG | M10: EG | V10: C₄H₁₁NO₂ (DEA) | W10: 105.136 | Z10: =SUM(Z7:Z9) -> 0 | AA10: can be solved
C11: Molar Composition | M11: Molar Composition | V11: C₆H₁₅NO₃ (TEA) | W11: 149.188
C12: AM | E12: =E5/$E$3 -> 1 | M12: AM | O12: =O5/$O$3 -> 1 | V12: C₂H₆O₂ (EG) | W12: 62.07 | Y12: AM Balance ( in=out )
C13: EO | M13: EO | Y13: =E5 -> 257.95375 | AA13: ṅ10
C14: MEA | M14: MEA | Y14: ṅ10 | Z14: = | AA14: =Y13 -> 257.95375 | AB14: kmol/hr AM
C15: DEA | M15: DEA
C16: TEA | M16: TEA | Y16: Energy Balance
C17: EG | M17: EG | Y17: ΔĖp + ΔĖk + ΔḢ = Q̇ + Ẇs
C18: Vapour Fraction | E18: 1 | M18: Vapour Fraction | O18: 0
C19: Total Mole Fraction | E19: =SUM(E12:E17) -> 1 | M19: Total Mole Fraction | O19: =SUM(O12:O17) -> 1 | Y19: Assumptions:
C20: T (°C) | E20: 10 | M20: T (°C) | O20: 50 | Y20: 1 | Z20: There is no changes in elevation of height in each unit system, ΔĖp = 0
C21: P (atm) | E21: 1 | M21: P (atm) | O21: 1 | Y21: 2 | Z21: There is no changes in velocity in each unit system, ΔĖk = 0
C22: H (kJ/hr) | E22: =Z38 -> -138511.7 | M22: H (kJ/hr) | O22: =AB38 -> -4849643.8 | Y22: 3 | Z22: There is no moving parts in each unit system, Ẇs = 0
P23: S10
B24: S8 | Y24: Reference state: | Z24: AM(v, | AB24: 25 | AC24: °C, 1 atm)
Y25: Substance | Z25: Stream 8 | AB25: Stream 10
Z26: ṅ in (kmol/hr) | AA26: Ĥ in (kJ/kmol) | AB26: ṅ out (kmol/hr) | AC26: Ĥ out (kJ/kmol)
Y27: AM (v) | Z27: =E5 -> 257.95375 | AA27: =AA46 -> -536.96332 | AB27: - | AC27: -
Y28: EO (v) | Z28: - | AA28: - | AB28: - | AC28: -
Y29: MEA (v) | Z29: - | AA29: - | AB29: - | AC29: -
Y30: DEA (v) | Z30: - | AA30: - | AB30: - | AC30: -
Y31: TEA (v) | Z31: - | AA31: - | AB31: - | AC31: -
Y32: AM (l) | Z32: - | AA32: - | AB32: =O5 -> 257.95375 | AC32: =AA68 -> -18800.44
Y33: EO (l) | Z33: - | AA33: - | AB33: - | AC33: -
Y34: MEA (l) | Z34: - | AA34: - | AB34: - | AC34: -
Y35: DEA (l) | Z35: - | AA35: - | AB35: - | AC35: -
Y36: TEA (l) | Z36: - | AA36: - | AB36: - | AC36: -
Y37: EG (v) | Z37: - | AA37: - | AB37: - | AC37: -
Y38: Total Enthalpy, H (kJ/hr) | Z38: =Z27*AA27 -> -138511.7 | AB38: =AB32*AC32 -> -4849643.8
Z41: Ĥ1
Y42: NH₃ (v,298.15K,1atm) | AB42: NH₃ (v,283.15K,1atm)
Y44: From Database, Table 1.3, at 283.15K,
...

Sheet Distillation Column 1 
M2: S11
L5: Total Mass Flowrate (kg/hr) | N5: =N9*R8+N10*R9+N11*R10 -> 11588.625
L6: Total Molar Flowrate (kmol/hr) | N6: =SUM(N8:N13) -> 208.62009 | Q6: Components | R6: Molecular Weight (kg/kmol) | T6: Degree of Freedom Analysis
L7: Components Molar Flowrate (kmol/hr) | Q7: NH₃ (AM) | R7: =17.031 -> 17.031 | T7: No. unkown labeled variable = | U7: 6 | V7: (ṅ11a, ṅ11b, ṅ11c, ṅ12a, ṅ12b, ṅ12c)
L8: AM | Q8: C₂H₄O (EO) | R8: 44.053 | T8: No. material balance spesies = | U8: -4 | V8: (EO, MEA, DEA, TEA)
L9: EO | M9: ṅ11a | N9: =V26 -> 68.071127 | Q9: C₂H₇NO (MEA) | R9: 61.083 | T9: No. process specification equation = | U9: -2 | V9: Ps (① ṅ11c is 1% DEA in S9 ② ṅ12a is 2% MEA in S9)
L10: MEA | M10: ṅ11b | N10: =V31 -> 140.44148 | Q10: C₄H₁₁NO₂ (DEA) | R10: 105.136
L11: DEA | M11: ṅ11c | N11: =V17 -> 0.10748073 | Q11: C₆H₁₅NO₃ (TEA) | R11: 149.188 | U11: =SUM(U7:U9) -> 0 | V11: can be solved
L12: TEA | Q12: C₂H₆O₂ (EG) | R12: 62.07
E13: Total Mass Flowrate (kg/hr) | G13: =G17*R8+G18*R9+G19*R10+G20*R11 -> 15554.88 | L13: EG
E14: Total Molar Flowrate (kmol/hr) | G14: =SUM(G16:G21) -> 240.04029 | L14: Molar Composition | T14: Ps ①
E15: Components Molar Flowrate (kmol/hr) | L15: AM | T15: ṅ11c is 1% DEA in S9
E16: AM | L16: EO | N16: =N9/$N$6 -> 0.32629229 | T16: 0.01(10.7488) | U16: = | V16: ṅ11c
E17: EO | F17: ṅ9a | G17: ='Phase Separator'!G53 -> 68.071127 | L17: MEA | N17: =N10/$N$6 -> 0.67319251 | T17: ṅ11c | U17: = | V17: =1%*G19 -> 0.10748073 | W17: kmol/hr DEA
E18: MEA | F18: ṅ9b | G18: ='Phase Separator'!G54 -> 143.30764 | L18: DEA | N18: =N11/$N$6 -> 0.00051519835
E19: DEA | F19: ṅ9c | G19: ='Phase Separator'!G55 -> 10.748073 | L19: TEA | T19: Ps ②
E20: TEA | F20: ṅ9d | G20: ='Phase Separator'!G56 -> 17.913455 | L20: EG | T20: ṅ12a is 2% MEA in S9
E21: EG | L21: Vapour Fraction | N21: 1 | T21: 0.02(143.3174) | U21: = | V21: ṅ12a
E22: Molar Composition | L22: Total Mole Fraction | N22: =SUM(N15:N20) -> 1 | T22: ṅ12a | U22: = | V22: =2%*G18 -> 2.8661527 | W22: kmol/hr MEA
E23: AM | L23: T (°C) | N23: 170
E24: EO | G24: =G17/$G$14 -> 0.28358209 | L24: P (atm) | N24: 1 | T24: EO Balance ( in=out)
E25: MEA | G25: =G18/$G$14 -> 0.59701493 | L25: H (kJ/hr) | N25: =W65 -> 2604648.3 | T25: =G17 -> 68.071127 | U25: = | V25: ṅ11a
E26: DEA | G26: =G19/$G$14 -> 0.044776119 | T26: ṅ11a | U26: = | V26: =T25 -> 68.071127 | W26: kmol/hr EO
E27: TEA | G27: =G20/$G$14 -> 0.074626866
E28: EG | T28: MEA Balance ( in=out )
E29: Vapour Fraction | G29: =0 -> 0 | T29: =G18 -> 143.30764 | U29: = | V29: ṅ11b | W29: + | X29: =I49 -> 2.8661527
E30: Total Mole Fraction | G30: =SUM(G23:G28) -> 1 | T30: ṅ11b | U30: = | V30: 143.3174-2.8663
E31: T (°C) | G31: 10 | T31: ṅ11b | U31: = | V31: =T29-X29 -> 140.44148 | W31: kmol/hr MEA
E32: P (atm) | G32: 1
E33: H (kJ/hr) | G33: =U65 -> -14954359 | T33: DEA Balance ( in=out )
H34: S9 | T34: =G19 -> 10.748073 | U34: = | V34: =N11 -> 0.10748073 | W34: + | X34: ṅ12b
T35: ṅ12b | U35: = | V35: 10.7488-0.1075
T36: ṅ12b | U36: = | V36: =T34-V34 -> 10.640592 | W36: kmol/hr DEA
T38: TEA Balance ( in=out )
T39: =G20 -> 17.913455 | U39: = | V39: ṅ12c
T40: ṅ12c | U40: = | V40: =T39 -> 17.913455 | W40: kmol/hr TEA
G44: Total Mass Flowrate (kg/hr) | I44: =I49*R9+I50*R10+I51*R11 -> 3966.2549 | T44: Energy Balance
G45: Total Molar Flowrate (kmol/hr) | I45: =SUM(I47:I51) -> 31.420199 | T45: ΔĖp + ΔĖk + ΔḢ = Q̇ + Ẇs
G46: Components Molar Flowrate (kmol/hr)
G47: AM | T47: Assumptions:
...

Sheet Distillation Column 2
X3: Degree of Freedom Analysis
C4: Total Mass Flowrate (kg/hr) | E4: =E9*U7+E10*U8+E11*U9 -> 3966.2549 | L4: Total Mass Flowrate (kg/hr) | N4: =N10*U8+N11*U9 -> 2304.4927 | T4: Components | U4: Molecular Weight (kg/kmol) | X4: No. unkown labeled variable = | AA4: 5 | AB4: (ṅ13a, ṅ13b, ṅ13c, ṅ14a, ṅ14b)
C5: Total Molar Flowrate (kmol/hr) | E5: =SUM(E7:E12) -> 31.420199 | L5: Total Molar Flowrate (kmol/hr) | N5: =SUM(N7:N12) -> 15.541162 | T5: NH₃ (AM) | U5: =17.031 -> 17.031 | X5: No. of material balance = | AA5: -3 | AB5: (MEA, DEA, TEA)
C6: Components Molar Flowrate (kmol/hr) | L6: Components Molar Flowrate (kmol/hr) | T6: C₂H₄O (EO) | U6: 44.053 | X6: No. process specification equation = | AA6: -2 | AB6: Ps (① ṅ13a is 65% DEA in S12
C7: AM | L7: AM | T7: C₂H₇NO (MEA) | U7: 61.083 | AB7: ② ṅ13b is 97% DEA in S12)
C8: EO | L8: EO | T8: C₄H₁₁NO₂ (DEA) | U8: 105.136 | AA8: =SUM(AA4:AA6) -> 0 | AB8: can be solved
C9: MEA | D9: ṅ12a | E9: ='Distillation Column 1 '!I49 -> 2.8661527 | L9: MEA | T9: C₆H₁₅NO₃ (TEA) | U9: 149.188
C10: DEA | D10: ṅ12b | E10: ='Distillation Column 1 '!I50 -> 10.640592 | L10: DEA | M10: ṅ14a | N10: =Z31 -> 0.31921776 | T10: C₂H₆O₂ (EG) | U10: 62.07
C11: TEA | D11: ṅ12c | E11: ='Distillation Column 1 '!I51 -> 17.913455 | L11: TEA | M11: ṅ14b | N11: =Z41 -> 15.221944
C12: EG | L12: EG | X12: Ps ①
C13: Molar Composition | L13: Molar Composition | X13: ṅ13a is 65% DEA in S12
C14: AM | L14: AM | X14: 0.65ṅ13 | Y14: = | Z14: 0.97ṅ12b
C15: EO | L15: EO | X15: 0.65ṅ13 | Y15: = | Z15: 0.97(10.6413)
C16: MEA | E16: =E9/$E$5 -> 0.091220068 | L16: MEA | X16: ṅ13 | Y16: = | Z16: =(97%*E10)/65% -> 15.879037 | AA16: kmol/hr
C17: DEA | E17: =E10/$E$5 -> 0.3386545 | L17: DEA | N17: =N10/N5 -> 0.020540148
C18: TEA | E18: =E11/$E$5 -> 0.57012543 | L18: TEA | N18: =N11/$N$5 -> 0.97945985 | X18: Ps ②
C19: EG | L19: EG | X19: ṅ13b is 97% DEA in S12
C20: Vapour Fraction | E20: 0 | L20: Vapour Fraction | N20: 0 | X20: ṅ13b | Y20: = | Z20: 0.97ṅ12b
C21: Total Mole Fraction | E21: =SUM(E14:E19) -> 1 | L21: Total Mole Fraction | N21: =SUM(N14:N19) -> 1 | X21: ṅ13b | Y21: = | Z21: 0.97(10.6413)
C22: T (°C) | E22: 250 | L22: T (°C) | N22: 335 | X22: ṅ13b | Y22: = | Z22: =97%*E10 -> 10.321374 | AA22: kmol/hr DEA
C23: P (atm) | E23: 1 | L23: P (atm) | N23: 1
C24: H (kJ/hr) | E24: =Y64 -> -785407.13 | L24: H (kJ/hr) | N24: =AC64 -> 197749.9 | X24: MEA Balance ( in=out )
B25: S12 | N25: S14 | X25: ṅ12a | Y25: = | Z25: ṅ13a
X26: ṅ13a | Y26: = | Z26: =E9 -> 2.8661527 | AA26: kmol/hr MEA
X28: DEA Balance ( in=out )
X29: ṅ12b | Y29: = | Z29: ṅ13b | AA29: + | AB29: ṅ14a
X30: ṅ14a | Y30: = | Z30: 10.6413-10.3221
X31: ṅ14a | Y31: = | Z31: =E10-Z22 -> 0.31921776 | AA31: kmol/hr DEA
X33: TEA Balance in S13,
F34: Total Mass Flowrate (kg/hr) | H34: =H39*U7+H40*U8+H41*U9 -> 1661.7623 | X34: ṅ13 | Y34: = | Z34: ṅ13a | AA34: + | AB34: ṅ13b | AC34: + | AD34: ṅ13c
F35: Total Molar Flowrate (kmol/hr) | H35: =SUM(H37:H42) -> 15.879037 | X35: ṅ13c | Y35: = | Z35: 15.8801-2.8663-10.3221
F36: Components Molar Flowrate (kmol/hr) | X36: ṅ13c | Y36: = | Z36: =Z16-Z26-Z22 -> 2.6915103 | AA36: kmol/hr TEA
F37: AM
F38: EO | X38: TEA Balance ( in=out )
F39: MEA | G39: ṅ13a | H39: =Z26 -> 2.8661527 | X39: ṅ12c | Y39: = | Z39: ṅ13c | AA39: + | AB39: ṅ14b
F40: DEA | G40: ṅ13b | H40: =Z22 -> 10.321374 | X40: ṅ14b | Y40: = | Z40: 17.9147-2.6917
F41: TEA | G41: ṅ13c | H41: =Z36 -> 2.6915103 | X41: ṅ14b | Y41: = | Z41: =E11-Z36 -> 15.221944 | AA41: kmol/hr TEA
F42: EG
F43: Molar Composition | X43: Energy Balance
F44: AM | X44: ΔĖp + ΔĖk + ΔḢ = Q̇ + Ẇs
...

Sheet Cooler 2
C3: Total Mass Flowrate (kg/hr) | E3: =E7*R5+E8*R6+E9*R7 -> 11588.625 | L3: Total Mass Flowrate (kg/hr) | N3: =N7*R5+N8*R6+N9*R7 -> 11588.625 | Q3: Components | R3: Molecular Weight (kg/kmol) | T3: Degree of Freedom Analysis
C4: Total Molar Flowrate (kmol/hr) | E4: =SUM(E6:E11) -> 208.62009 | L4: Total Molar Flowrate (kmol/hr) | N4: =SUM(N6:N11) -> 208.62009 | Q4: NH₃ (AM) | R4: =17.031 -> 17.031 | T4: No. unkown labeled variable = | W4: 3 | X4: (ṅ15a, ṅ15b, ṅ15c)
C5: Components Molar Flowrate (kmol/hr) | L5: Components Molar Flowrate (kmol/hr) | Q5: C₂H₄O (EO) | R5: 44.053 | T5: No. of material balance = | W5: -3 | X5: (EO, MEA, DEA)
C6: AM | L6: AM | Q6: C₂H₇NO (MEA) | R6: 61.083 | T6: No. process specification equation = | W6: 0 | X6: Ps
C7: EO | D7: ṅ11a | E7: ='Distillation Column 1 '!N9 -> 68.071127 | L7: EO | M7: ṅ15a | N7: =V11 -> 68.071127 | Q7: C₄H₁₁NO₂ (DEA) | R7: 105.136 | W7: =SUM(W4:W6) -> 0 | X7: can be solved
C8: MEA | D8: ṅ11b | E8: ='Distillation Column 1 '!N10 -> 140.44148 | L8: MEA | M8: ṅ15b | N8: =V15 -> 140.44148 | Q8: C₆H₁₅NO₃ (TEA) | R8: 149.188
C9: DEA | D9: ṅ11c | E9: ='Distillation Column 1 '!N11 -> 0.10748073 | L9: DEA | M9: ṅ15c | N9: =V19 -> 0.10748073 | Q9: C₂H₆O₂ (EG) | R9: 62.07 | T9: EO Balance ( in=out )
C10: TEA | L10: TEA | T10: =E7 -> 68.071127 | U10: = | V10: ṅ15a
C11: EG | L11: EG | T11: ṅ15a | U11: = | V11: =T10 -> 68.071127 | W11: kmol/hr EO
C12: Molar Composition | L12: Molar Composition
C13: AM | L13: AM | T13: MEA Balance ( in=out )
C14: EO | E14: =E7/$E$4 -> 0.32629229 | L14: EO | N14: =N7/$N$4 -> 0.32629229 | T14: =E8 -> 140.44148 | U14: = | V14: ṅ15b
C15: MEA | E15: =E8/$E$4 -> 0.67319251 | L15: MEA | N15: =N8/$N$4 -> 0.67319251 | T15: ṅ15b | U15: = | V15: =T14 -> 140.44148 | W15: kmol/hr MEA
C16: DEA | E16: =E9/$E$4 -> 0.00051519835 | L16: DEA | N16: =N9/$N$4 -> 0.00051519835
C17: TEA | L17: TEA | T17: DEA Balance ( in=out )
C18: EG | L18: EG | T18: =E9 -> 0.10748073 | U18: = | V18: ṅ15c
C19: Vapour Fraction | E19: 1 | L19: Vapour Fraction | N19: 0 | T19: ṅ15c | U19: = | V19: =T18 -> 0.10748073 | W19: kmol/hr DEA
C20: Total Mole Fraction | E20: =SUM(E13:E18) -> 1 | L20: Total Mole Fraction | N20: =SUM(N13:N18) -> 1
C21: T (°C) | E21: 170 | L21: T (°C) | N21: 6 | T21: Energy Balance
C22: P (atm) | E22: 1 | L22: P (atm) | N22: 1 | T22: ΔĖp + ΔĖk + ΔḢ = Q̇ + Ẇs
C23: H (kJ/hr) | E23: =U42 -> 2604648.3 | L23: H (kJ/hr) | N23: =W42 -> -11767908
B24: S11 | O24: S15 | T24: Assumptions:
T25: 1 | U25: There is no changes in elevation of height in each unit system, ΔĖp = 0
T26: 2 | U26: There is no changes in velocity in each unit system, ΔĖk = 0
T27: 3 | U27: There is no moving parts in each unit system, Ẇs = 0
T29: Reference state: | U29: EO,MEA,DEA,(v, | W29: 25 | X29: °C, 1 atm)
T30: Substance | U30: Stream 11 | W30: Stream 15
U31: ṅ in (kmol/hr) | V31: Ĥ in (kJ/kmol) | W31: ṅ out (kmol/hr) | X31: Ĥ out (kJ/kmol)
T32: AM (g） | U32: - | V32: - | W32: - | X32: -
T33: EO (l） | U33: - | V33: - | W33: =N7 -> 68.071127 | X33: =V85 -> -26807.148
T34: MEA (l） | U34: - | V34: - | W34: =N8 -> 140.44148 | X34: =V106 -> -70731.298
T35: DEA (l） | U35: - | V35: - | W35: =N9 -> 0.10748073 | X35: =V127 -> -88450.69
T36: TEA (l） | U36: - | V36: - | W36: - | X36: -
T37: EO (v） | U37: =E7 -> 68.071127 | V37: =V50 -> 8363.3151 | W37: - | X37: -
T38: MEA (v） | U38: =E8 -> 140.44148 | V38: =V57 -> 14474.07 | W38: - | X38: -
T39: DEA (v) | U39: =E9 -> 0.10748073 | V39: =V64 -> 24080.055 | W39: - | X39: -
T40: TEA (v) | U40: - | V40: - | W40: - | X40: -
T41: EG (v) | U41: - | V41: - | W41: - | X41: -
T42: Total Enthalpy, H (kJ/hr) | U42: =U37*V37+U38*V38+U39*V39 -> 2604648.3 | W42: =W33*X33+W34*X34+W35*X35 -> -11767908
U45: Ĥ1
...

Sheet Liquid-liquid Extractor 
P12: Components | Q12: Molecular Weight (kg/kmol) | S12: Degree of Freedom Analysis
K13: Total Mass Flowrate (kg/hr) | M13: =M21*Q18 -> 19423.574 | P13: NH₃ (AM) | Q13: =17.031 -> 17.031 | S13: No. unkown labeled variable = | V13: 6 | W13: (ṅ16, ṅ17, ṅ18a, ṅ18b, ṅ18c, ṅ18d)
K14: Total Molar Flowrate (kmol/hr) | M14: =SUM(M16:M21) -> 312.93014 | P14: C₂H₄O (EO) | Q14: 44.053 | S14: No. of material balance = | V14: -4 | W14: (EO, MEA, DEA, EG)
K15: Components Molar Flowrate (kmol/hr) | P15: C₂H₇NO (MEA) | Q15: 61.083 | S15: No. process specification equation = | V15: -2 | W15: Ps (① ṅ16 is 1.5 S15
C16: Total Mass Flowrate (kg/hr) | E16: =E20*Q14+E21*Q15+E22*Q16 -> 11588.625 | K16: AM | P16: C₄H₁₁NO₂ (DEA) | Q16: 105.136 | W16: ② ṅ17 is 98% of EO in S15)
C17: Total Molar Flowrate (kmol/hr) | E17: =SUM(E19:E24) -> 208.62009 | K17: EO | P17: C₆H₁₅NO₃ (TEA) | Q17: 149.188 | V17: =SUM(V13:V15) -> 0 | W17: can be solved
C18: Components Molar Flowrate (kmol/hr) | K18: MEA | P18: C₂H₆O₂ (EG) | Q18: 62.07
C19: AM | K19: DEA | S19: Ps ①
C20: EO | D20: ṅ15a | E20: ='Cooler 2'!N7 -> 68.071127 | K20: TEA | S20: ṅ16 is 1.5 S15
C21: MEA | D21: ṅ15b | E21: ='Cooler 2'!N8 -> 140.44148 | K21: EG | L21: ṅ16 | M21: =U22 -> 312.93014 | S21: ṅ16 | T21: = | U21: 1.5(208.6201)
C22: DEA | D22: ṅ15c | E22: ='Cooler 2'!N9 -> 0.10748073 | K22: Molar Composition | S22: ṅ16 | T22: = | U22: =1.5*E17 -> 312.93014 | V22: kmol/hr EG
C23: TEA | K23: AM
C24: EG | K24: EO | S24: Ps ②
C25: Molar Composition | K25: MEA | S25: ṅ17 is 98% of EO in S15
C26: AM | K26: DEA | S26: ṅ17 | T26: = | U26: 0.98(68.0758)
C27: EO | E27: =E20/$E$17 -> 0.32629229 | K27: TEA | S27: ṅ17 | T27: = | U27: =98%*E20 -> 66.709705 | V27: kmol/hr EO
C28: MEA | E28: =E21/$E$17 -> 0.67319251 | K28: EG | M28: =M21/$M$14 -> 1
C29: DEA | E29: =E22/$E$17 -> 0.00051519835 | K29: Vapour Fraction | M29: 0 | S29: EO Balance ( in=out ）
C30: TEA | K30: Total Mole Fraction | M30: =SUM(M23:M28) -> 1 | S30: ṅ15a | T30: = | U30: ṅ17 | V30: + | W30: ṅ18a
C31: EG | K31: T (°C) | M31: 6 | S31: ṅ18a | T31: = | U31: 68.0758-66.7142
C32: Vapour Fraction | E32: 0 | K32: P (atm) | M32: 1 | S32: ṅ18a | T32: = | U32: =E20-U27 -> 1.3614225 | V32: kmol/hr EO
C33: Total Mole Fraction | E33: =SUM(E26:E31) -> 1 | J33: S16 | K33: H (kJ/hr) | M33: =V68 -> -22289384
C34: T (°C) | E34: 6 | S34: MEA Balance ( in=out ）
C35: P (atm) | E35: 1 | S35: ṅ15b | T35: = | U35: ṅ18b
C36: H (kJ/hr) | E36: =T68 -> -11767908 | S36: ṅ18b | T36: = | U36: =E21 -> 140.44148 | V36: kmol/hr MEA
B38: S15 | P38: S18
S39: DEA Balance ( in=out ）
S40: ṅ15c | T40: = | U40: ṅ18c
M41: Total Mass Flowrate (kg/hr) | O41: =O45*Q14+O46*Q15+O47*Q16+O49*Q18 -> 28073.436 | S41: ṅ18c | T41: = | U41: =E22 -> 0.10748073 | V41: kmol/hr MEA
M42: Total Molar Flowrate (kmol/hr) | O42: =SUM(O44:O49) -> 454.84052
M43: Components Molar Flowrate (kmol/hr) | S43: EG Balance ( in=out ）
H44: S17 | M44: AM | S44: ṅ16 | T44: = | U44: ṅ18d
F45: Total Mass Flowrate (kg/hr) | H45: =H49*Q14 -> 2938.7626 | M45: EO | N45: ṅ18a | O45: =U32 -> 1.3614225 | S45: ṅ18d | T45: = | U45: =U22 -> 312.93014 | V45: kmol/hr EG
F46: Total Molar Flowrate (kmol/hr) | H46: =SUM(H48:H53) -> 66.709705 | M46: MEA | N46: ṅ18b | O46: =U36 -> 140.44148
F47: Components Molar Flowrate (kmol/hr) | M47: DEA | N47: ṅ18c | O47: =U41 -> 0.10748073 | S47: Energy Balance
F48: AM | M48: TEA | S48: ΔĖp + ΔĖk + ΔḢ = Q̇ + Ẇs
F49: EO | G49: ṅ17 | H49: =U27 -> 66.709705 | M49: EG | N49: ṅ18d | O49: =U45 -> 312.93014
F50: MEA | M50: Molar Composition | S50: Assumptions:
F51: DEA | M51: AM | S51: 1 | T51: There is no changes in elevation of height in each unit system, ΔĖp = 0
F52: TEA | M52: EO | O52: =O45/$O$42 -> 0.0029931866 | S52: 2 | T52: There is no changes in velocity in each unit system, ΔĖk = 0
...

Sheet Distillation Column 3
S5: Components | T5: Molecular Weight (kg/kmol) | V5: Degree of Freedom Analysis
L6: S20 | S6: NH₃ (AM) | T6: =17.031 -> 17.031 | V6: No. unkown labeled variable = | X6: 5 | Y6: (ṅ19a, ṅ19b, ṅ20a, ṅ20b, ṅ20c)
S7: C₂H₄O (EO) | T7: 44.053 | V7: No. of material balance = | X7: -4 | Y7: (EO, MEA, DEA, EG)
S8: C₂H₇NO (MEA) | T8: 61.083 | V8: No. process specification equation = | X8: -1 | Y8: Ps (ṅ19b is 99% ṅ18b)
J9: Total Mass Flowrate (kg/hr) | L9: =L14*T8+L15*T9+L17*T11 -> 19520.66 | S9: C₄H₁₁NO₂ (DEA) | T9: 105.136 | X9: =SUM(X6:X8) -> 0 | Y9: can be solved
J10: Total Molar Flowrate (kmol/hr) | L10: =SUM(L12:L17) -> 314.44203 | S10: C₆H₁₅NO₃ (TEA) | T10: 149.188
J11: Components Molar Flowrate (kmol/hr) | S11: C₂H₆O₂ (EG) | T11: 62.07
J12: AM | V12: Ps
J13: EO | V13: ṅ19b is 99% ṅ18b
J14: MEA | K14: ṅ20a | L14: =X24 -> 1.4044148 | V14: ṅ19b | W14: = | X14: 0.99(140.4510)
J15: DEA | K15: ṅ20b | L15: =X28 -> 0.10748073 | V15: ṅ19b | W15: = | X15: =99%*E22 -> 139.03707 | Y15: kmol/hr MEA
J16: TEA
C17: Total Mass Flowrate (kg/hr) | E17: =E21*T7+E22*T8+E23*T9+E25*T11 -> 28073.436 | J17: EG | K17: ṅ20c | L17: =X32 -> 312.93014 | V17: EO Balance ( in=out )
C18: Total Molar Flowrate (kmol/hr) | E18: =SUM(E20:E25) -> 454.84052 | J18: Molar Composition | V18: ṅ18a | W18: = | X18: ṅ19a
C19: Components Molar Flowrate (kmol/hr) | J19: AM | V19: ṅ19a | W19: = | X19: =E21 -> 1.3614225 | Y19: kmol/hr EO
C20: AM | J20: EO
C21: EO | D21: ṅ18a | E21: ='Liquid-liquid Extractor '!O45 -> 1.3614225 | J21: MEA | L21: =L14/$L$10 -> 0.0044663712 | V21: MEA Balance ( in=out ）
C22: MEA | D22: ṅ18b | E22: ='Liquid-liquid Extractor '!O46 -> 140.44148 | J22: DEA | L22: =L15/$L$10 -> 0.00034181412 | V22: ṅ18b | W22: = | X22: ṅ19b | Y22: + | Z22: ṅ20a
C23: DEA | D23: ṅ18c | E23: ='Liquid-liquid Extractor '!O47 -> 0.10748073 | J23: TEA | V23: ṅ20a | W23: = | X23: 140.4510-139.0465
C24: TEA | J24: EG | L24: =L17/$L$10 -> 0.99519181 | V24: ṅ20a | W24: = | X24: =E22-X15 -> 1.4044148 | Y24: kmol/hr MEA
C25: EG | D25: ṅ18d | E25: ='Liquid-liquid Extractor '!O49 -> 312.93014 | J25: Vapour Fraction | L25: 0
C26: Molar Composition | J26: Total Mole Fraction | L26: =SUM(L19:L24) -> 1 | V26: DEA Balance ( in=out )
C27: AM | J27: T (°C) | L27: 190 | V27: ṅ18c | W27: = | X27: ṅ20b
C28: EO | E28: =E21/$E$18 -> 0.0029931866 | J28: P (atm) | L28: 1 | V28: ṅ20b | W28: = | X28: =E23 -> 0.10748073 | Y28: kmol/hr DEA
C29: MEA | E29: =E22/$E$18 -> 0.30877082 | J29: H (kJ/hr) | L29: =AA57 -> -12312097
C30: DEA | E30: =E23/$E$18 -> 0.0002363042 | V30: EG Balance ( in=out )
C31: TEA | V31: ṅ18d | W31: = | X31: ṅ20c
C32: EG | E32: =E25/$E$18 -> 0.68799968 | V32: ṅ20c | W32: = | X32: =E25 -> 312.93014 | Y32: kmol/hr HX
C33: Vapour Fraction | E33: 0
C34: Total Mole Fraction | E34: =SUM(E27:E32) -> 1
C35: T (°C) | E35: 6
C36: P (atm) | E36: 1 | V36: Energy Balance
C37: H (kJ/hr) | E37: =W57 -> -32268995 | V37: ΔĖp + ΔĖk + ΔḢ = Q̇ + Ẇs
B38: S18
V39: Assumptions:
V40: 1 | W40: There is no changes in elevation of height in each unit system, ΔĖp = 0
V41: 2 | W41: There is no changes in velocity in each unit system, ΔĖk = 0
V42: 3 | W42: There is no moving parts in each unit system, Ẇs = 0
V44: Reference state: | W44: EO,MEA,DEA,EG,(v, | Y44: 25 | Z44: °C, 1 atm)
V45: Substance | W45: Stream 18 | Y45: Stream 19 | AA45: Stream 20
...

Sheet Heater 4
H4: Total Mass Flowrate (kg/hr) | J4: =J8*Q6 -> 2938.7626 | P4: Components | Q4: Molecular Weight (kg/kmol) | S4: Degree of Freedom Analysis
H5: Total Molar Flowrate (kmol/hr) | J5: =SUM(J7:J12) -> 66.709705 | P5: NH₃ (AM) | Q5: =17.031 -> 17.031 | S5: No. unkown labeled variable = | T5: 1 | U5: (ṅ21)
H6: Components Molar Flowrate (kmol/hr) | P6: C₂H₄O (EO) | Q6: 44.053 | S6: No. material balance spesies = | T6: -1 | U6: (EO)
H7: AM | P7: C₂H₇NO (MEA) | Q7: 61.083 | S7: No. process specification equation = | T7: 0 | U7: Ps
H8: EO | I8: ṅ17 | J8: ='Liquid-liquid Extractor '!H49 -> 66.709705 | P8: C₄H₁₁NO₂ (DEA) | Q8: 105.136 | T8: =SUM(T5:T7) -> 0 | U8: can be solved
H9: MEA | P9: C₆H₁₅NO₃ (TEA) | Q9: 149.188
H10: DEA | P10: C₂H₆O₂ (EG) | Q10: 62.07
H11: TEA | S11: EO Balance ( in=out )
H12: EG | S12: ṅ17 | T12: = | U12: ṅ21
H13: Molar Composition | S13: =J8 -> 66.709705 | T13: = | U13: ṅ21
H14: AM | S14: ṅ21 | T14: = | U14: =S13 -> 66.709705 | V14: kmol/hr EO
H15: EO | J15: =J8/$J$5 -> 1
H16: MEA
H17: DEA | S17: Energy Balance
H18: TEA | S18: ΔĖp + ΔĖk + ΔḢ = Q̇ + Ẇs
H19: EG
H20: Vapour Fraction | J20: 0 | S20: Assumptions:
H21: Total Mole Fraction | J21: =SUM(J14:J19) -> 1 | S21: 1 | T21: There is no changes in elevation of height in each unit system, ΔĖp = 0
H22: T (°C) | J22: 6 | S22: 2 | T22: There is no changes in velocity in each unit system, ΔĖk = 0
H23: P (atm) | J23: 1 | S23: 3 | T23: There is no moving parts in each unit system, Ẇs = 0
G24: S17 | H24: H (kJ/hr) | J24: =T40 -> -1788296.9
S25: Reference state: | T25: EO (v, | U25: 25 | V25: °C, 1 atm)
S26: Substance | T26: Stream 17 | V26: Stream 21
T27: ṅ in (kmol/hr) | U27: Ĥ in (kJ/kmol) | V27: ṅ out (kmol/hr) | W27: Ĥ out (kJ/kmol)
S28: AM (l) | T28: - | U28: - | V28: - | W28: -
S29: EO (l) | T29: =J8 -> 66.709705 | U29: =U61 -> -26807.148 | V29: - | W29: -
S30: MEA (l) | T30: - | U30: - | V30: - | W30: -
K31: Total Mass Flowrate (kg/hr) | M31: =M35*Q6 -> 2938.7626 | S31: DEA (l) | T31: - | U31: - | V31: - | W31: -
K32: Total Molar Flowrate (kmol/hr) | M32: =SUM(M34:M39) -> 66.709705 | S32: TEA (l) | T32: - | U32: - | V32: - | W32: -
K33: Components Molar Flowrate (kmol/hr) | S33: EG (l) | T33: - | U33: - | V33: - | W33: -
K34: AM | S34: AM (v) | T34: - | U34: - | V34: - | W34: -
